<?xml version="1.0"?>
<robot name="diff_drive_robot">

  <!-- Define the robot base -->
  <link name="base_link">
    <visual>
      <geometry>
        <box size="0.2 0.2 0.1"/>
      </geometry>
      <material name="grey">
        <color rgba="0.5 0.5 0.5 1"/>
      </material>
    </visual>
  </link>

  <!-- Define the left wheel -->
  <link name="left_wheel">
    <visual>
      <geometry>
        <cylinder length="0.05" radius="0.1"/>
      </geometry>
      <material name="black">
        <color rgba="0 0 0 1"/>
      </material>
    </visual>
    <collision>
      <geometry>
        <cylinder length="0.05" radius="0.1"/>
      </geometry>
    </collision>
  </link>

  <!-- Define the right wheel -->
  <link name="right_wheel">
    <visual>
      <geometry>
        <cylinder length="0.05" radius="0.1"/>
      </geometry>
      <material name="black">
        <color rgba="0 0 0 1"/>
      </material>
    </visual>
    <collision>
      <geometry>
        <cylinder length="0.05" radius="0.1"/>
      </geometry>
    </collision>
  </link>

  <!-- Define the left wheel joint -->
  <joint name="left_wheel_joint" type="continuous">
    <parent link="base_link"/>
    <child link="left_wheel"/>
    <origin xyz="0.15 0 -0.05" rpy="0 0 0"/>
    <axis xyz="0 0 1"/>
  </joint>

  <!-- Define the right wheel joint -->
  <joint name="right_wheel_joint" type="continuous">
    <parent link="base_link"/>
    <child link="right_wheel"/>
    <origin xyz="0.15 0 0.05" rpy="0 0 0"/>
    <axis xyz="0 0 1"/>
  </joint>

  <!-- Define the robot -->
  <robot>
    <link name="base_link"/>
    <joint name="left_wheel_joint" type="continuous">
      <parent link="base_link"/>
      <child link="left_wheel"/>
      <origin xyz="0.15 0 -0.05" rpy="0 0 0"/>
      <axis xyz="0 0 1"/>
    </joint>
    <joint name="right_wheel_joint" type="continuous">
      <parent link="base_link"/>
      <child link="right_wheel"/>
      <origin xyz="0.15 0 0.05" rpy="0 0 0"/>
      <axis xyz="0 0 1"/>
    </joint>
  </robot>

</robot>

